{"uuid": "70dfd471-c2c9-4222-8a53-b960dbd69695", "children": ["d29f5393-7efb-4268-a20b-2b7bbf8f929e"], "befores": [{"name": "setup", "status": "passed", "start": 1619078494125, "stop": 1619078506667}], "afters": [{"name": "setup::0", "status": "broken", "statusDetails": {"message": "selenium.common.exceptions.InvalidSessionIdException: Message: invalid session id\n\n", "trace": "  File \"C:\\Users\\52128856\\AppData\\Local\\Programs\\Python\\Python37\\lib\\site-packages\\allure_commons\\_allure.py\", line 197, in __call__\n    return self._fixture_function(*args, **kwargs)\n  File \"C:\\Users\\52128856\\AppData\\Local\\Programs\\Python\\Python37\\lib\\site-packages\\_pytest\\fixtures.py\", line 939, in _teardown_yield_fixture\n    next(it)\n  File \"D:\\AutomationPythonQA\\AutomationPython\\testCases\\conftest.py\", line 32, in setup\n    driver.close()\n  File \"C:\\Users\\52128856\\AppData\\Local\\Programs\\Python\\Python37\\lib\\site-packages\\selenium\\webdriver\\remote\\webdriver.py\", line 688, in close\n    self.execute(Command.CLOSE)\n  File \"C:\\Users\\52128856\\AppData\\Local\\Programs\\Python\\Python37\\lib\\site-packages\\selenium\\webdriver\\remote\\webdriver.py\", line 321, in execute\n    self.error_handler.check_response(response)\n  File \"C:\\Users\\52128856\\AppData\\Local\\Programs\\Python\\Python37\\lib\\site-packages\\selenium\\webdriver\\remote\\errorhandler.py\", line 242, in check_response\n    raise exception_class(message, screen, stacktrace)\n"}, "start": 1619078537934, "stop": 1619078538698}], "start": 1619078494125, "stop": 1619078538698}