{"uuid": "85ab0fbf-5195-4c22-b5f1-9c6dc318de62", "children": ["b8a7e927-8f3f-4a1f-b031-50a6baf0aa6e"], "befores": [{"name": "setup", "status": "passed", "start": 1619073638572, "stop": 1619073650333}], "afters": [{"name": "setup::0", "status": "broken", "statusDetails": {"message": "selenium.common.exceptions.InvalidSessionIdException: Message: invalid session id\n\n", "trace": "  File \"C:\\Users\\52128856\\AppData\\Local\\Programs\\Python\\Python37\\lib\\site-packages\\allure_commons\\_allure.py\", line 197, in __call__\n    return self._fixture_function(*args, **kwargs)\n  File \"C:\\Users\\52128856\\AppData\\Local\\Programs\\Python\\Python37\\lib\\site-packages\\_pytest\\fixtures.py\", line 939, in _teardown_yield_fixture\n    next(it)\n  File \"D:\\AutomationPythonQA\\AutomationPython\\testCases\\conftest.py\", line 32, in setup\n    driver.close()\n  File \"C:\\Users\\52128856\\AppData\\Local\\Programs\\Python\\Python37\\lib\\site-packages\\selenium\\webdriver\\remote\\webdriver.py\", line 688, in close\n    self.execute(Command.CLOSE)\n  File \"C:\\Users\\52128856\\AppData\\Local\\Programs\\Python\\Python37\\lib\\site-packages\\selenium\\webdriver\\remote\\webdriver.py\", line 321, in execute\n    self.error_handler.check_response(response)\n  File \"C:\\Users\\52128856\\AppData\\Local\\Programs\\Python\\Python37\\lib\\site-packages\\selenium\\webdriver\\remote\\errorhandler.py\", line 242, in check_response\n    raise exception_class(message, screen, stacktrace)\n"}, "start": 1619073685869, "stop": 1619073686489}], "start": 1619073638572, "stop": 1619073686489}